Training data shape: (2291, 500)
Val data shape: (327, 500)
Test data shape: (656, 500)
Training started....
Traceback (most recent call last):
  File "/home-mscluster/tmazarura/HonoursResearch/src/ClassifierPCA.py", line 84, in <module>
    history = model.fit(
        X_train, y_train,
    ...<6 lines>...
                   ]
    )
  File "/home-mscluster/tmazarura/miniconda3/lib/python3.13/site-packages/keras/src/utils/traceback_utils.py", line 122, in error_handler
    raise e.with_traceback(filtered_tb) from None
  File "/home-mscluster/tmazarura/miniconda3/lib/python3.13/site-packages/wandb/integration/keras/callbacks/model_checkpoint.py", line 128, in on_epoch_end
    super().on_epoch_end(epoch, logs)
    ~~~~~~~~~~~~~~~~~~~~^^^^^^^^^^^^^
KeyError: 'Failed to format this callback filepath: "nmf_model_{epoch:02d}_{batch:02d}.keras". Reason: \'batch\''
